Workbook

Sheet Rekap
A1: Daftar Pembayaran Honorarium Penelitian dan PPM Agustus - Oktober 2026 (Ajuan Rekap September 2026) - Ikhtisar per Kelompok dan Bulan
A2: Sesuai rincian 202609_feb_unpas_rincian_honorarium_penelitian_ppm_rev_06: nama sesuai SK 022/Unpas.FEB.D/SK/II/2026; tarif mengajar reguler pagi per bulan; pensiunan memakai tabel tarif DLB.
A3: Bulan yang sudah dibayar dengan daftar lama dicatat sebesar realisasinya (tanpa voucher baru). Selisihnya dibayar atau dipotong di voucher Oktober 2026 (kolom KOREKSI, sheet Koreksi_Terbayar).
A5: Honorarium Penelitian
A6: Kelompok | B6: Agustus 2026 | C6: September 2026 | D6: Oktober 2026 | E6: Jumlah
A7: Status | B7: Sudah dibayar (daftar lama) | C7: Sudah dibayar (daftar lama) | D7: Daftar ini, termasuk koreksi
A8: Kelompok 1 | B8: 2963688 | C8: 2963688 | D8: ='Penelitian Okt 2026'!K6 -> 2963688 | E8: =SUM(B8:D8) -> 8891064
A9: Kelompok 2 | B9: 3005100 | C9: 3005100 | D9: ='Penelitian Okt 2026'!K7 -> 3005100 | E9: =SUM(B9:D9) -> 9015300
A10: Kelompok 3 | B10: 3047388 | C10: 3047388 | D10: ='Penelitian Okt 2026'!K8 -> 3311988 | E10: =SUM(B10:D10) -> 9406764
A11: Kelompok 4 | B11: 2694504 | C11: 2694504 | D11: ='Penelitian Okt 2026'!K9 -> 2694504 | E11: =SUM(B11:D11) -> 8083512
A12: Kelompok 5 | B12: 3082584 | C12: 3082584 | D12: ='Penelitian Okt 2026'!K10 -> 3082584 | E12: =SUM(B12:D12) -> 9247752
A13: Kelompok 6 | B13: 2565984 | C13: 2565984 | D13: ='Penelitian Okt 2026'!K11 -> 2565984 | E13: =SUM(B13:D13) -> 7697952
A14: Kelompok 7 | B14: 2587944 | C14: 2587944 | D14: ='Penelitian Okt 2026'!K12 -> 2587944 | E14: =SUM(B14:D14) -> 7763832
A15: Kelompok 8 | B15: 3250176 | C15: 3250176 | D15: ='Penelitian Okt 2026'!K13 -> 3325776 | E15: =SUM(B15:D15) -> 9826128
A16: Kelompok 9 | B16: 3064944 | C16: 3064944 | D16: ='Penelitian Okt 2026'!K14 -> 3064944 | E16: =SUM(B16:D16) -> 9194832
A17: Kelompok 10 | B17: 3657780 | C17: 3657780 | D17: ='Penelitian Okt 2026'!K15 -> 4054188 | E17: =SUM(B17:D17) -> 11369748
A18: Kelompok 11 | B18: 2993844 | C18: 2993844 | D18: ='Penelitian Okt 2026'!K16 -> 2474076 | E18: =SUM(B18:D18) -> 8461764
A19: Kelompok 12 | B19: 3553212 | C19: 3553212 | D19: ='Penelitian Okt 2026'!K17 -> 3370512 | E19: =SUM(B19:D19) -> 10476936
... A22: Hibah Dikti | B22: 2587404 | C22: 2587404 | D22: ='Penelitian Okt 2026'!K20 -> 2587404 | E22: =SUM(B22:D22) -> 7762212
A23: JUMLAH DIBAYAR | B23: =SUM(B8:B22) -> 46212324 | C23: =SUM(C8:C22) -> 46212324 | D23: =SUM(D8:D22) -> 46354464 | E23: =SUM(E8:E22) -> 138779112
A24: Honor sesuai rincian | B24: 46424700 | C24: 46268556 | D24: 46085856 | E24: =SUM(B24:D24) -> 138779112
A25: Selisih (koreksi dipindah) | B25: =B23-B24 -> -212376 | C25: =C23-C24 -> -56232 | D25: =D23-D24 -> 268608 | E25: =E23-E24 -> 0
A26: Rekap September O37 | E26: 138779112
A27: Cek | E27: =IF(AND(E23=E26,E24=E26),"COCOK","BEDA") -> COCOK
A30: Honorarium PPM
A31: Kelompok | B31: Agustus 2026 | C31: September 2026 | D31: Oktober 2026 | E31: Jumlah
A32: Status | B32: Sudah dibayar (daftar lama) | C32: Daftar ini | D32: Daftar ini, termasuk koreksi
A33: Kelompok 1 | B33: 3292368 | C33: ='PPM Sep 2026'!G6 -> 3292368 | D33: ='PPM Okt 2026'!K6 -> 3292368 | E33: =SUM(B33:D33) -> 9877104
A34: Kelompok 2 | B34: 3745524 | C34: ='PPM Sep 2026'!G7 -> 3745524 | D34: ='PPM Okt 2026'!K7 -> 3745524 | E34: =SUM(B34:D34) -> 11236572
A35: Kelompok 3 | B35: 3622584 | C35: ='PPM Sep 2026'!G8 -> 3622584 | D35: ='PPM Okt 2026'!K8 -> 3622584 | E35: =SUM(B35:D35) -> 10867752
A36: Kelompok 4 | B36: 4001136 | C36: ='PPM Sep 2026'!G9 -> 4001136 | D36: ='PPM Okt 2026'!K9 -> 4001136 | E36: =SUM(B36:D36) -> 12003408
A37: Kelompok 5 | B37: 2955960 | C37: ='PPM Sep 2026'!G10 -> 2993760 | D37: ='PPM Okt 2026'!K10 -> 2993760 | E37: =SUM(B37:D37) -> 8943480
A38: Kelompok 6 | B38: 3327576 | C38: ='PPM Sep 2026'!G11 -> 3154320 | D38: ='PPM Okt 2026'!K11 -> 2981064 | E38: =SUM(B38:D38) -> 9462960
A39: Kelompok 7 | B39: 3243228 | C39: ='PPM Sep 2026'!G12 -> 3331428 | D39: ='PPM Okt 2026'!K12 -> 3419628 | E39: =SUM(B39:D39) -> 9994284
A40: Kelompok 8 | B40: 3534924 | C40: ='PPM Sep 2026'!G13 -> 3534924 | D40: ='PPM Okt 2026'!K13 -> 3534924 | E40: =SUM(B40:D40) -> 10604772
A41: Kelompok 9 | B41: 3953868 | C41: ='PPM Sep 2026'!G14 -> 3953868 | D41: ='PPM Okt 2026'!K14 -> 3953868 | E41: =SUM(B41:D41) -> 11861604
A42: Kelompok 10 | B42: 3804480 | C42: ='PPM Sep 2026'!G15 -> 3698712 | D42: ='PPM Okt 2026'!K15 -> 3786888 | E42: =SUM(B42:D42) -> 11290080
A43: Kelompok 11 | B43: 3777936 | C43: ='PPM Sep 2026'!G16 -> 3813936 | D43: ='PPM Okt 2026'!K16 -> 3667236 | E43: =SUM(B43:D43) -> 11259108
A44: Kelompok 12 | B44: 3408912 | C44: ='PPM Sep 2026'!G17 -> 3408912 | D44: ='PPM Okt 2026'!K17 -> 3408912 | E44: =SUM(B44:D44) -> 10226736
A45: Kelompok 13 | B45: 3543828 | C45: ='PPM Sep 2026'!G18 -> 3717084 | D45: ='PPM Okt 2026'!K18 -> 3890340 | E45: =SUM(B45:D45) -> 11151252
...

Sheet Koreksi_Terbayar
A1: Koreksi Honor yang Sudah Dibayar dengan Daftar Lama - Dibayar atau Dipotong pada Pembayaran Oktober 2026
A2: PPM Agustus 2026 dan Penelitian Agustus-September 2026 sudah dibayar dengan daftar fakultas (sheet Realisasi, 46.212.324 per program per bulan). Selisih terhadap tarif rincian masuk voucher Oktober 2026 program yang sama (kolom KOREKSI).
A3: Positif = kurang bayar (ditambahkan); negatif = lebih bayar (dipotong). Arahan WD II 25 September 2026.
A5: No | B5: Nama (SK 022/2026) | C5: NoPeg | D5: Program | E5: Bulan | F5: Kelompok | G5: Tarif dibayar | H5: Tarif seharusnya | I5: Selisih tarif | J5: Selisih honor | K5: Keterangan
A6: 1 | B6: Erry S. R. Pangestu, S.E., M.M. | C6: D11030 | D6: PPM | E6: Agustus 2026 | F6: Kelompok 6 | G6: 78225 | H6: 63787 | I6: =H6-G6 -> -14438 | J6: =I6*3*4 -> -173256 | K6: Tarif di daftar tertukar dengan Dikdik Kusdiana (seharusnya 63.787)
A7: 2 | B7: Mohamad Razab Iryadana, S.T., M.M. | C7: D11069 | D7: PPM | E7: Agustus 2026 | F7: Kelompok 7 | G7: 53812 | H7: 61162 | I7: =H7-G7 -> 7350 | J7: =I7*3*4 -> 88200 | K7: Tarif aplikasi 61.162 sejak Juli 2026 (pendidikan S3)
A8: 3 | B8: Dr. Endang Rostiana, S.E., M.T. | C8: D11044 | D8: PPM | E8: Agustus 2026 | F8: Kelompok 10 | G8: 71138 | H8: 74287 | I8: =H8-G8 -> 3149 | J8: =I8*3*4 -> 37788 | K8: Tarif aplikasi 74.287 sejak Agustus 2026 (Lektor Kepala)
A9: 4 | B9: Hj. Neni M. Santoso, S.E., M.Si. | C9: D11007 | D9: PPM | E9: Agustus 2026 | F9: Kelompok 10 | G9: 56963 | H9: 61162 | I9: =H9-G9 -> 4199 | J9: =I9*3*4 -> 50388 | K9: Agustus tarif dosen tetap 61.162; mulai September tarif DLB IIIb 45.000
A10: 5 | B10: R. Muchamad Noch Drs., M.Ak., Ak., C.A. | C10: D12007 | D10: PPM | E10: Agustus 2026 | F10: Kelompok 11 | G10: 54000 | H10: 57000 | I10: =H10-G10 -> 3000 | J10: =I10*3*4 -> 36000 | K10: Pensiunan: tarif DLB IV/b 57.000 sesuai SK pensiun
A11: 6 | B11: Dr. Dikdik Kusdiana, S.E., M.T. | C11: D11029 | D11: PPM | E11: Agustus 2026 | F11: Kelompok 13 | G11: 63787 | H11: 78225 | I11: =H11-G11 -> 14438 | J11: =I11*3*4 -> 173256 | K11: Tarif di daftar tertukar dengan Erry S. R. Pangestu (seharusnya 78.225)
A12: 7 | B12: Mohamad Razab Iryadana, S.T., M.M. | C12: D11069 | D12: Penelitian | E12: Agustus 2026 | F12: Kelompok 3 | G12: 53812 | H12: 61162 | I12: =H12-G12 -> 7350 | J12: =I12*3*4 -> 88200 | K12: Tarif aplikasi 61.162 sejak Juli 2026 (pendidikan S3)
A13: 8 | B13: Dr. Endang Rostiana, S.E., M.T. | C13: D11044 | D13: Penelitian | E13: Agustus 2026 | F13: Kelompok 10 | G13: 71138 | H13: 74287 | I13: =H13-G13 -> 3149 | J13: =I13*3*4 -> 37788 | K13: Tarif aplikasi 74.287 sejak Agustus 2026 (Lektor Kepala)
A14: 9 | B14: Hj. Neni M. Santoso, S.E., M.Si. | C14: D11007 | D14: Penelitian | E14: Agustus 2026 | F14: Kelompok 10 | G14: 56963 | H14: 61162 | I14: =H14-G14 -> 4199 | J14: =I14*3*4 -> 50388 | K14: Agustus tarif dosen tetap 61.162; mulai September tarif DLB IIIb 45.000
A15: 10 | B15: Dr. Dikdik Kusdiana, S.E., M.T. | C15: D11029 | D15: Penelitian | E15: Agustus 2026 | F15: Kelompok 10 | G15: 63787 | H15: 78225 | I15: =H15-G15 -> 14438 | J15: =I15*3*4 -> 173256 | K15: Tarif di daftar tertukar dengan Erry S. R. Pangestu (seharusnya 78.225)
A16: 11 | B16: Erry S. R. Pangestu, S.E., M.M. | C16: D11030 | D16: Penelitian | E16: Agustus 2026 | F16: Kelompok 11 | G16: 78225 | H16: 63787 | I16: =H16-G16 -> -14438 | J16: =I16*3*4 -> -173256 | K16: Tarif di daftar tertukar dengan Dikdik Kusdiana (seharusnya 63.787)
A17: 12 | B17: R. Muchamad Noch Drs., M.Ak., Ak., C.A. | C17: D12007 | D17: Penelitian | E17: Agustus 2026 | F17: Kelompok 14 | G17: 54000 | H17: 57000 | I17: =H17-G17 -> 3000 | J17: =I17*3*4 -> 36000 | K17: Pensiunan: tarif DLB IV/b 57.000 sesuai SK pensiun
... A24: 19 | B24: R. Muchamad Noch Drs., M.Ak., Ak., C.A. | C24: D12007 | D24: Penelitian | E24: September 2026 | F24: Kelompok 14 | G24: 54000 | H24: 57000 | I24: =H24-G24 -> 3000 | J24: =I24*3*4 -> 36000 | K24: Pensiunan: tarif DLB IV/b 57.000 sesuai SK pensiun
B25: JUMLAH | J25: =SUM(J6:J24) -> 480984
B27: Ringkasan per orang - masuk voucher Oktober 2026
B28: Nama (SK 022/2026) | C28: NoPeg | D28: Kel. Penelitian | E28: Kel. PPM | F28: Koreksi Penelitian | G28: Koreksi PPM | H28: Jumlah | I28: Tindak lanjut
B29: Dr. Dikdik Kusdiana, S.E., M.T. | C29: D11029 | D29: Kelompok 10 | E29: Kelompok 13 | F29: =SUMIFS($J$6:$J$24,$C$6:$C$24,C29,$D$6:$D$24,"Penelitian") -> 346512 | G29: =SUMIFS($J$6:$J$24,$C$6:$C$24,C29,$D$6:$D$24,"PPM") -> 173256 | H29: =F29+G29 -> 519768 | I29: Voucher Oktober 2026 - Penelitian Kelompok 10: ditambah 346.512; PPM Kelompok 13: ditambah 173.256
B30: Mohamad Razab Iryadana, S.T., M.M. | C30: D11069 | D30: Kelompok 3 | E30: Kelompok 7 | F30: =SUMIFS($J$6:$J$24,$C$6:$C$24,C30,$D$6:$D$24,"Penelitian") -> 176400 | G30: =SUMIFS($J$6:$J$24,$C$6:$C$24,C30,$D$6:$D$24,"PPM") -> 88200 | H30: =F30+G30 -> 264600 | I30: Voucher Oktober 2026 - Penelitian Kelompok 3: ditambah 176.400; PPM Kelompok 7: ditambah 88.200
B31: Dr. Endang Rostiana, S.E., M.T. | C31: D11044 | D31: Kelompok 10 | E31: Kelompok 10 | F31: =SUMIFS($J$6:$J$24,$C$6:$C$24,C31,$D$6:$D$24,"Penelitian") -> 75576 | G31: =SUMIFS($J$6:$J$24,$C$6:$C$24,C31,$D$6:$D$24,"PPM") -> 37788 | H31: =F31+G31 -> 113364 | I31: Voucher Oktober 2026 - Penelitian Kelompok 10: ditambah 75.576; PPM Kelompok 10: ditambah 37.788
B32: R. Muchamad Noch Drs., M.Ak., Ak., C.A. | C32: D12007 | D32: Kelompok 14 | E32: Kelompok 11 | F32: =SUMIFS($J$6:$J$24,$C$6:$C$24,C32,$D$6:$D$24,"Penelitian") -> 72000 | G32: =SUMIFS($J$6:$J$24,$C$6:$C$24,C32,$D$6:$D$24,"PPM") -> 36000 | H32: =F32+G32 -> 108000 | I32: Voucher Oktober 2026 - Penelitian Kelompok 14: ditambah 72.000; PPM Kelompok 11: ditambah 36.000
B33: Mochammad Ridwan, S.E., Ak., M.Si. | C33: D11055 | D33: Kelompok 8 | E33: Kelompok 5 | F33: =SUMIFS($J$6:$J$24,$C$6:$C$24,C33,$D$6:$D$24,"Penelitian") -> 37800 | G33: =SUMIFS($J$6:$J$24,$C$6:$C$24,C33,$D$6:$D$24,"PPM") -> 0 | H33: =F33+G33 -> 37800 | I33: Voucher Oktober 2026 - Penelitian Kelompok 8: ditambah 37.800
B34: Hj. Neni M. Santoso, S.E., M.Si. | C34: D11007 | D34: Kelompok 10 | E34: Kelompok 10 | F34: =SUMIFS($J$6:$J$24,$C$6:$C$24,C34,$D$6:$D$24,"Penelitian") -> -93168 | G34: =SUMIFS($J$6:$J$24,$C$6:$C$24,C34,$D$6:$D$24,"PPM") -> 50388 | H34: =F34+G34 -> -42780 | I34: Voucher Oktober 2026 - Penelitian Kelompok 10: dipotong 93.168; PPM Kelompok 10: ditambah 50.388
B35: Erry S. R. Pangestu, S.E., M.M. | C35: D11030 | D35: Kelompok 11 | E35: Kelompok 6 | F35: =SUMIFS($J$6:$J$24,$C$6:$C$24,C35,$D$6:$D$24,"Penelitian") -> -346512 | G35: =SUMIFS($J$6:$J$24,$C$6:$C$24,C35,$D$6:$D$24,"PPM") -> -173256 | H35: =F35+G35 -> -519768 | I35: Voucher Oktober 2026 - Penelitian Kelompok 11: dipotong 346.512; PPM Kelompok 6: dipotong 173.256
B36: JUMLAH | F36: =SUM(F29:F35) -> 268608 | G36: =SUM(G29:G35) -> 212376 | H36: =SUM(H29:H35) -> 480984

Sheet Penelitian Okt 2026
A1: REKAPITULASI HONORARIUM BULANAN SETARA 3 SKS PENELITIAN
A2: FAKULTAS EKONOMI DAN BISNIS UNIVERSITAS PASUNDAN
A3: TAHUN AKADEMIK 2026/2027 - BULAN OKTOBER 2026 (BULAN KE-3 DARI 6)
A4: Termasuk koreksi honor Penelitian Agustus-September 2026 yang sudah dibayar dengan daftar lama (sheet Koreksi_Terbayar)
A5: No. | B5: Kelompok | F5: Dosen | G5: Honor Bulan Ini (Rp) | J5: Koreksi (Rp) | K5: Jumlah Dana (Rp) | L5: Keterangan
A6: 1 | B6: Kelompok 1 | F6: 4 | G6: =SUM(I49:I52) -> 2963688 | J6: =SUM(J49:J52) -> 0 | K6: =D54 -> 2963688
A7: 2 | B7: Kelompok 2 | F7: 4 | G7: =SUM(I83:I86) -> 3005100 | J7: =SUM(J83:J86) -> 0 | K7: =D88 -> 3005100 | L7: Tarif DLB: Popo Suryana (DLB IVc)
A8: 3 | B8: Kelompok 3 | F8: 4 | G8: =SUM(I117:I120) -> 3135588 | J8: =SUM(J117:J120) -> 176400 | K8: =D122 -> 3311988 | L8: Koreksi: Mohamad Razab Iryadana +176.400
A9: 4 | B9: Kelompok 4 | F9: 4 | G9: =SUM(I151:I154) -> 2694504 | J9: =SUM(J151:J154) -> 0 | K9: =D156 -> 2694504
A10: 5 | B10: Kelompok 5 | F10: 4 | G10: =SUM(I185:I188) -> 3082584 | J10: =SUM(J185:J188) -> 0 | K10: =D190 -> 3082584
A11: 6 | B11: Kelompok 6 | F11: 3 | G11: =SUM(I219:I221) -> 2565984 | J11: =SUM(J219:J221) -> 0 | K11: =D223 -> 2565984
A12: 7 | B12: Kelompok 7 | F12: 3 | G12: =SUM(I252:I254) -> 2587944 | J12: =SUM(J252:J254) -> 0 | K12: =D256 -> 2587944 | L12: Tarif DLB: Atty Tri Juniarti (DLB IVc)
A13: 8 | B13: Kelompok 8 | F13: 4 | G13: =SUM(I285:I288) -> 3287976 | J13: =SUM(J285:J288) -> 37800 | K13: =D290 -> 3325776 | L13: Koreksi: Mochammad Ridwan +37.800
A14: 9 | B14: Kelompok 9 | F14: 4 | G14: =SUM(I319:I322) -> 3064944 | J14: =SUM(J319:J322) -> 0 | K14: =D324 -> 3064944
A15: 10 | B15: Kelompok 10 | F15: 5 | G15: =SUM(I353:I357) -> 3725268 | J15: =SUM(J353:J357) -> 328920 | K15: =D359 -> 4054188 | L15: Tarif DLB: Neni M. Santoso (DLB IIIb) Koreksi: Endang Rostiana +75.576; Neni M. Santoso -93.168; Dikdik Kusdiana +346.512
A16: 11 | B16: Kelompok 11 | F16: 4 | G16: =SUM(I388:I391) -> 2820588 | J16: =SUM(J388:J391) -> -346512 | K16: =D393 -> 2474076 | L16: Koreksi: Erry S. R. Pangestu -346.512
A17: 12 | B17: Kelompok 12 | F17: 4 | G17: =SUM(I422:I425) -> 3370512 | J17: =SUM(J422:J425) -> 0 | K17: =D427 -> 3370512 | L17: Tarif DLB: Liza Laila Nurwulan (DLB IVd)
A18: 13 | B18: Kelompok 13 | F18: 5 | G18: =SUM(I456:I460) -> 4064112 | J18: =SUM(J456:J460) -> 0 | K18: =D462 -> 4064112
A19: 14 | B19: Kelompok 14 | F19: 4 | G19: =SUM(I491:I494) -> 3129660 | J19: =SUM(J491:J494) -> 72000 | K19: =D496 -> 3201660 | L19: Tarif DLB: R. Muchamad Noch (DLB IVb) Koreksi: R. Muchamad Noch +72.000
A20: 15 | B20: Hibah Dikti | F20: 3 | G20: =SUM(I525:I527) -> 2587404 | J20: =SUM(J525:J527) -> 0 | K20: =D529 -> 2587404
A21: JUMLAH | F21: =SUM(F6:F20) -> 59 | G21: =SUM(G6:G20) -> 46085856 | J21: =SUM(J6:J20) -> 268608 | K21: =SUM(K6:K20) -> 46354464
H23: Bandung, ....................................
A24: Wakil Dekan Bidang Riset dan Kerjasama, | H24: Wakil Dekan Bidang Perencanaan, Sumber Daya, Keuangan, dan Sistem Teknologi Informasi,
A29: Dr. Endang Rostiana, S.E., M.T. | H29: Mochammad Ridwan, S.E., Ak., M.Si.
D31: Mengetahui, Dekan,
D36: Prof. Dr. H. Juanim, S.E., M.Si.
B39: FAKULTAS EKONOMI DAN BISNIS
B40: UNIVERSITAS PASUNDAN
B41: Jl. Tamansari No. 4–8, Bandung 40116
B42: Telp. 022-4233646; 4208363 | e-mail: fekon@unpas.ac.id
A44: BUKTI KAS KELUAR
L45: No. Bukti | N45: : | O45: ………………….
A46: Dibayarkan kepada : | D46: Anggota Kelompok 1 Penelitian
A48: NO. | B48: NAMA | F48: JUMLAH | G48: SKS | H48: TARIF | I48: HONOR | J48: KOREKSI | K48: DIBAYAR | L48: TANDA TANGAN
A49: 1. | B49: Prof. Dr. Hj. Erni Rusyani, S.E., M.M. | F49: 4 | G49: 3 | H49: 80062 | I49: =F49*G49*H49 -> 960744 | J49: 0 | K49: =I49+J49 -> 960744 | L49: 1 | M49: ………………
A50: 2. | B50: Dr. H. Undang Juju, S.E., M.Si. | F50: 4 | G50: 3 | H50: 76912 | I50: =F50*G50*H50 -> 922944 | J50: 0 | K50: =I50+J50 -> 922944 | N50: 2 | O50: ………………
A51: 3. | B51: Desy Nurrohmah, S.Si., M.M. | F51: 4 | G51: 3 | H51: 45000 | I51: =F51*G51*H51 -> 540000 | J51: 0 | K51: =I51+J51 -> 540000 | L51: 3 | M51: ………………
A52: 4. | B52: Intan Ramdhaniatulfitri, S.E., M.E. | F52: 4 | G52: 3 | H52: 45000 | I52: =F52*G52*H52 -> 540000 | J52: 0 | K52: =I52+J52 -> 540000 | N52: 4 | O52: ………………
A54: Jumlah Uang | C54: : | D54: =SUM(K49:K52) -> 2963688
A55: Terbilang | C55: : | D55: Dua juta sembilan ratus enam puluh tiga ribu enam ratus delapan puluh delapan rupiah
...

Sheet PPM Sep 2026
A1: REKAPITULASI HONORARIUM BULANAN SETARA 3 SKS PPM
A2: FAKULTAS EKONOMI DAN BISNIS UNIVERSITAS PASUNDAN
A3: TAHUN AKADEMIK 2026/2027 - BULAN SEPTEMBER 2026 (BULAN KE-2 DARI 4)
A5: No. | B5: Kelompok | F5: Dosen | G5: Jumlah Dana (Rp) | J5: Keterangan
A6: 1 | B6: Kelompok 1 | F6: 4 | G6: =D52 -> 3292368
A7: 2 | B7: Kelompok 2 | F7: 5 | G7: =D87 -> 3745524
A8: 3 | B8: Kelompok 3 | F8: 5 | G8: =D122 -> 3622584
A9: 4 | B9: Kelompok 4 | F9: 5 | G9: =D157 -> 4001136
A10: 5 | B10: Kelompok 5 | F10: 4 | G10: =D191 -> 2993760
A11: 6 | B11: Kelompok 6 | F11: 4 | G11: =D225 -> 3154320 | J11: Tarif DLB: Popo Suryana (DLB IVc)
A12: 7 | B12: Kelompok 7 | F12: 4 | G12: =D259 -> 3331428
A13: 8 | B13: Kelompok 8 | F13: 4 | G13: =D293 -> 3534924
A14: 9 | B14: Kelompok 9 | F14: 5 | G14: =D328 -> 3953868
A15: 10 | B15: Kelompok 10 | F15: 5 | G15: =D363 -> 3698712 | J15: Tarif DLB: Atty Tri Juniarti (DLB IVc); Neni M. Santoso (DLB IIIb)
A16: 11 | B16: Kelompok 11 | F16: 5 | G16: =D398 -> 3813936 | J16: Tarif DLB: R. Muchamad Noch (DLB IVb)
A17: 12 | B17: Kelompok 12 | F17: 4 | G17: =D432 -> 3408912
A18: 13 | B18: Kelompok 13 | F18: 5 | G18: =D467 -> 3717084
A19: JUMLAH | F19: =SUM(F6:F18) -> 59 | G19: =SUM(G6:G18) -> 46268556
H21: Bandung, ....................................
A22: Wakil Dekan Bidang Riset dan Kerjasama, | H22: Wakil Dekan Bidang Perencanaan, Sumber Daya, Keuangan, dan Sistem Teknologi Informasi,
A27: Dr. Endang Rostiana, S.E., M.T. | H27: Mochammad Ridwan, S.E., Ak., M.Si.
D29: Mengetahui, Dekan,
D34: Prof. Dr. H. Juanim, S.E., M.Si.
B37: FAKULTAS EKONOMI DAN BISNIS
B38: UNIVERSITAS PASUNDAN
B39: Jl. Tamansari No. 4–8, Bandung 40116
B40: Telp. 022-4233646; 4208363 | e-mail: fekon@unpas.ac.id
A42: BUKTI KAS KELUAR
J43: No. Bukti | L43: : | M43: ………………….
A44: Dibayarkan kepada : | D44: Anggota Kelompok 1 PPM
A46: NO. | B46: NAMA | F46: JUMLAH | G46: SKS | H46: TARIF | I46: JUMLAH | J46: TANDA TANGAN
A47: 1. | B47: Bingky Aresia Landarica, S.E., M.Ak. | F47: 4 | G47: 3 | H47: 54652 | I47: =F47*G47*H47 -> 655824 | J47: 1 | K47: ………………
A48: 2. | B48: Dr. Wasito, S.E., M.S.I.E. | F48: 4 | G48: 3 | H48: 71138 | I48: =F48*G48*H48 -> 853656 | L48: 2 | M48: ………………
A49: 3. | B49: Dr. Elvira Zeyn, S.E., M.Si., Ak., CA., CGAA. | F49: 4 | G49: 3 | H49: 74287 | I49: =F49*G49*H49 -> 891444 | J49: 3 | K49: ………………
A50: 4. | B50: Dr. H. Sasa S. Suratman, S.E., M.Sc., Ak., C.A. | F50: 4 | G50: 3 | H50: 74287 | I50: =F50*G50*H50 -> 891444 | L50: 4 | M50: ………………
A52: Jumlah Uang | C52: : | D52: =SUM(I47:I50) -> 3292368
A53: Terbilang | C53: : | D53: Tiga juta dua ratus sembilan puluh dua ribu tiga ratus enam puluh delapan rupiah
A54: Untuk keperluan | C54: : | D54: Honor Bulanan PPM Fakultas Setara 3 SKS
D55: Bulan September 2026
A57: MENYETUJUI : | D57: TANDA TANGAN | F57: TANGGAL | K57: NO. POS | M57: JUMLAH
...

Sheet PPM Okt 2026
A1: REKAPITULASI HONORARIUM BULANAN SETARA 3 SKS PPM
A2: FAKULTAS EKONOMI DAN BISNIS UNIVERSITAS PASUNDAN
A3: TAHUN AKADEMIK 2026/2027 - BULAN OKTOBER 2026 (BULAN KE-3 DARI 4)
A4: Termasuk koreksi honor PPM Agustus 2026 yang sudah dibayar dengan daftar lama (sheet Koreksi_Terbayar)
A5: No. | B5: Kelompok | F5: Dosen | G5: Honor Bulan Ini (Rp) | J5: Koreksi (Rp) | K5: Jumlah Dana (Rp) | L5: Keterangan
A6: 1 | B6: Kelompok 1 | F6: 4 | G6: =SUM(I47:I50) -> 3292368 | J6: =SUM(J47:J50) -> 0 | K6: =D52 -> 3292368
A7: 2 | B7: Kelompok 2 | F7: 5 | G7: =SUM(I81:I85) -> 3745524 | J7: =SUM(J81:J85) -> 0 | K7: =D87 -> 3745524
A8: 3 | B8: Kelompok 3 | F8: 5 | G8: =SUM(I116:I120) -> 3622584 | J8: =SUM(J116:J120) -> 0 | K8: =D122 -> 3622584
A9: 4 | B9: Kelompok 4 | F9: 5 | G9: =SUM(I151:I155) -> 4001136 | J9: =SUM(J151:J155) -> 0 | K9: =D157 -> 4001136
A10: 5 | B10: Kelompok 5 | F10: 4 | G10: =SUM(I186:I189) -> 2993760 | J10: =SUM(J186:J189) -> 0 | K10: =D191 -> 2993760
A11: 6 | B11: Kelompok 6 | F11: 4 | G11: =SUM(I220:I223) -> 3154320 | J11: =SUM(J220:J223) -> -173256 | K11: =D225 -> 2981064 | L11: Tarif DLB: Popo Suryana (DLB IVc) Koreksi: Erry S. R. Pangestu -173.256
A12: 7 | B12: Kelompok 7 | F12: 4 | G12: =SUM(I254:I257) -> 3331428 | J12: =SUM(J254:J257) -> 88200 | K12: =D259 -> 3419628 | L12: Koreksi: Mohamad Razab Iryadana +88.200
A13: 8 | B13: Kelompok 8 | F13: 4 | G13: =SUM(I288:I291) -> 3534924 | J13: =SUM(J288:J291) -> 0 | K13: =D293 -> 3534924
A14: 9 | B14: Kelompok 9 | F14: 5 | G14: =SUM(I322:I326) -> 3953868 | J14: =SUM(J322:J326) -> 0 | K14: =D328 -> 3953868
A15: 10 | B15: Kelompok 10 | F15: 5 | G15: =SUM(I357:I361) -> 3698712 | J15: =SUM(J357:J361) -> 88176 | K15: =D363 -> 3786888 | L15: Tarif DLB: Atty Tri Juniarti (DLB IVc); Neni M. Santoso (DLB IIIb) Koreksi: Endang Rostiana +37.788; Neni M. Santoso +50.388
A16: 11 | B16: Kelompok 11 | F16: 5 | G16: =SUM(I392:I396) -> 3631236 | J16: =SUM(J392:J396) -> 36000 | K16: =D398 -> 3667236 | L16: Tarif DLB: Liza Laila Nurwulan (DLB IVd); R. Muchamad Noch (DLB IVb) Koreksi: R. Muchamad Noch +36.000
A17: 12 | B17: Kelompok 12 | F17: 4 | G17: =SUM(I427:I430) -> 3408912 | J17: =SUM(J427:J430) -> 0 | K17: =D432 -> 3408912
A18: 13 | B18: Kelompok 13 | F18: 5 | G18: =SUM(I461:I465) -> 3717084 | J18: =SUM(J461:J465) -> 173256 | K18: =D467 -> 3890340 | L18: Koreksi: Dikdik Kusdiana +173.256
A19: JUMLAH | F19: =SUM(F6:F18) -> 59 | G19: =SUM(G6:G18) -> 46085856 | J19: =SUM(J6:J18) -> 212376 | K19: =SUM(K6:K18) -> 46298232
H21: Bandung, ....................................
A22: Wakil Dekan Bidang Riset dan Kerjasama, | H22: Wakil Dekan Bidang Perencanaan, Sumber Daya, Keuangan, dan Sistem Teknologi Informasi,
A27: Dr. Endang Rostiana, S.E., M.T. | H27: Mochammad Ridwan, S.E., Ak., M.Si.
D29: Mengetahui, Dekan,
D34: Prof. Dr. H. Juanim, S.E., M.Si.
B37: FAKULTAS EKONOMI DAN BISNIS
B38: UNIVERSITAS PASUNDAN
B39: Jl. Tamansari No. 4–8, Bandung 40116
B40: Telp. 022-4233646; 4208363 | e-mail: fekon@unpas.ac.id
A42: BUKTI KAS KELUAR
L43: No. Bukti | N43: : | O43: ………………….
A44: Dibayarkan kepada : | D44: Anggota Kelompok 1 PPM
A46: NO. | B46: NAMA | F46: JUMLAH | G46: SKS | H46: TARIF | I46: HONOR | J46: KOREKSI | K46: DIBAYAR | L46: TANDA TANGAN
A47: 1. | B47: Bingky Aresia Landarica, S.E., M.Ak. | F47: 4 | G47: 3 | H47: 54652 | I47: =F47*G47*H47 -> 655824 | J47: 0 | K47: =I47+J47 -> 655824 | L47: 1 | M47: ………………
A48: 2. | B48: Dr. Wasito, S.E., M.S.I.E. | F48: 4 | G48: 3 | H48: 71138 | I48: =F48*G48*H48 -> 853656 | J48: 0 | K48: =I48+J48 -> 853656 | N48: 2 | O48: ………………
A49: 3. | B49: Dr. Elvira Zeyn, S.E., M.Si., Ak., CA., CGAA. | F49: 4 | G49: 3 | H49: 74287 | I49: =F49*G49*H49 -> 891444 | J49: 0 | K49: =I49+J49 -> 891444 | L49: 3 | M49: ………………
A50: 4. | B50: Dr. H. Sasa S. Suratman, S.E., M.Sc., Ak., C.A. | F50: 4 | G50: 3 | H50: 74287 | I50: =F50*G50*H50 -> 891444 | J50: 0 | K50: =I50+J50 -> 891444 | N50: 4 | O50: ………………
A52: Jumlah Uang | C52: : | D52: =SUM(K47:K50) -> 3292368
A53: Terbilang | C53: : | D53: Tiga juta dua ratus sembilan puluh dua ribu tiga ratus enam puluh delapan rupiah
A54: Untuk keperluan | C54: : | D54: Honor Bulanan PPM Fakultas Setara 3 SKS
D55: Bulan Oktober 2026
...
